{"uuid": "7f3afd2c-58ed-41d1-b462-96d5b2fdb3d1", "children": ["e7966c43-7099-4cc7-8d51-87ef89dc28f7"], "befores": [{"name": "test_open", "status": "broken", "statusDetails": {"message": "selenium.common.exceptions.WebDriverException: Message: The requested resource could not be found, or a request was received using an HTTP method that is not supported by the mapped resource\n\n", "trace": "  File \"D:\\Python\\lib\\site-packages\\pluggy\\callers.py\", line 187, in _multicall\n    res = hook_impl.function(*args)\n  File \"D:\\Python\\lib\\site-packages\\_pytest\\fixtures.py\", line 1126, in pytest_fixture_setup\n    result = call_fixture_func(fixturefunc, request, kwargs)\n  File \"D:\\Python\\lib\\site-packages\\_pytest\\fixtures.py\", line 925, in call_fixture_func\n    fixture_result = next(generator)\n  File \"D:\\PycharmProjects\\pytest_auto\\testcases\\conftest.py\", line 42, in test_open\n    activity = app_driver.title()\n  File \"D:\\Python\\lib\\site-packages\\selenium\\webdriver\\remote\\webdriver.py\", line 342, in title\n    resp = self.execute(Command.GET_TITLE)\n  File \"D:\\Python\\lib\\site-packages\\selenium\\webdriver\\remote\\webdriver.py\", line 321, in execute\n    self.error_handler.check_response(response)\n  File \"D:\\Python\\lib\\site-packages\\selenium\\webdriver\\remote\\errorhandler.py\", line 242, in check_response\n    raise exception_class(message, screen, stacktrace)\n"}, "start": 1631107170371, "stop": 1631107193016}], "start": 1631107170371, "stop": 1631107193802}